Workbook
Name 金额: OFFSET(模型一!I1,0,0,COUNTA(模型一!I:I)-1)
Name 时间: OFFSET(模型一!A1,0,0,COUNTA(模型一!A:A)-1)
Name 资产: OFFSET(模型一!H1,0,0,COUNTA(模型一!H:H)-1)
Name 资金: OFFSET(模型一!G1,0,0,COUNTA(模型一!G:G)-1)

Sheet 模型一
A1: 日期 | B1: ESG300指数 | C1: 买卖金额 | D1: 买卖份数 | E1: 持有份数 | F1: 市值 | G1: 累计投入资金 | H1: 总资产 | I1: 利润 | J1: PE
C2: 2000 | D2: 单位：元
A3: 40451 | B3: 1.23009 | C3: 2000 | D3: 1625.8973 | E3: 1625.8973 | F3: 2000 | G3: 2000 | H3: 2000 | I3: 0 | J3: =VLOOKUP(A3,myPEPB!B:C,2) -> #N/A | L3: 日期 | M3: 每年投入本金 | N3: 累计投入本金 | O3: 总资产 | P3: 盈利金额 | Q3: 绝对收益率 | R3: 年化收益率 | T3: 40543 | U3: =VLOOKUP(T3,L:M,2) -> 8000 | V3: =-U3 -> -8000 | W3: 40543 | X3: =VLOOKUP(W3,L:M,2) -> 8000 | Y3: =-X3 -> -8000 | Z3: 40543 | AA3: =VLOOKUP(Z3,L:M,2) -> 8000 | AB3: =-AA3 -> -8000
A4: 40480 | B4: 1.39654 | C4: 2000 | D4: 1432.1108 | E4: 3058.0081 | F4: 4270.6306 | G4: 4000 | H4: 4270.6306 | I4: 270.6306 | J4: =VLOOKUP(A4,myPEPB!B:C,2) -> #N/A | L4: 40543 | M4: 8000 | N4: 8000 | O4: 7908.6759 | P4: -91.324067 | Q4: -0.011415508 | R4: -0.011415508 | T4: 40907 | U4: =VLOOKUP(T4,L:M,2) -> 24000 | V4: =-U4 -> -24000 | W4: 40907 | X4: =VLOOKUP(W4,L:M,2) -> 24000 | Y4: =-X4 -> -24000 | Z4: 40907 | AA4: =VLOOKUP(Z4,L:M,2) -> 24000 | AB4: =-AA4 -> -24000
A5: 40512 | B5: 1.31427 | C5: 2000 | D5: 1521.7573 | E5: 4579.7654 | F5: 6019.0483 | G5: 6000 | H5: 6019.0483 | I5: 19.04828 | J5: =VLOOKUP(A5,myPEPB!B:C,2) -> #N/A | L5: 40907 | M5: 24000 | N5: 32000 | O5: 25685.573 | P5: -6314.427 | Q5: -0.19732584 | R5: -0.16318665 | T5: 40907 | V5: =VLOOKUP(T5,L:O,4) -> 25685.573 | W5: 41274 | X5: =VLOOKUP(W5,L:M,2) -> 24000 | Y5: =-X5 -> -24000 | Z5: 41274 | AA5: =VLOOKUP(Z5,L:M,2) -> 24000 | AB5: =-AA5 -> -24000
A6: 40543 | B6: 1.29017 | C6: 2000 | D6: 1550.1833 | E6: 6129.9487 | F6: 7908.6759 | G6: 8000 | H6: 7908.6759 | I6: -91.324067 | J6: =VLOOKUP(A6,myPEPB!B:C,2) -> #N/A | L6: 41274 | M6: 24000 | N6: 56000 | O6: 52348.708 | P6: -3651.2923 | Q6: -0.065201648 | R6: -0.038781434 | V6: -0.16318665 | W6: 41274 | Y6: =VLOOKUP(W6,L:O,4) -> 52348.708 | Z6: 41639 | AA6: =VLOOKUP(Z6,L:M,2) -> 24000 | AB6: =-AA6 -> -24000
A7: 40574 | B7: 1.2747 | C7: 2000 | D7: 1568.9966 | E7: 7698.9453 | F7: 9813.8456 | G7: 10000 | H7: 9813.8456 | I7: -186.15437 | J7: =VLOOKUP(A7,myPEPB!B:C,2) -> #N/A | L7: 41639 | M7: 24000 | N7: 80000 | O7: 82813.626 | P7: 2813.6264 | Q7: 0.03517033 | R7: 0.015781488 | Y7: -0.038781434 | Z7: 41639 | AB7: =VLOOKUP(Z7,L:O,4) -> 82813.626
A8: 40602 | B8: 1.37611 | C8: 2000 | D8: 1453.3722 | E8: 9152.3175 | F8: 12594.596 | G8: 12000 | H8: 12594.596 | I8: 594.59567 | J8: =VLOOKUP(A8,myPEPB!B:C,2) -> #N/A | L8: 42004 | M8: 24000 | N8: 104000 | O8: 153292.71 | P8: 49292.715 | Q8: 0.47396841 | R8: 0.14842121 | AB8: 0.015781488
A9: 40633 | B9: 1.35039 | C9: 2000 | D9: 1481.0536 | E9: 10633.371 | F9: 14359.198 | G9: 14000 | H9: 14359.198 | I9: 359.19807 | J9: =VLOOKUP(A9,myPEPB!B:C,2) -> #N/A | L9: 42369 | M9: 24000 | N9: 128000 | O9: 214081.38 | P9: 86081.38 | Q9: 0.67251078 | R9: 0.16482525 | T9: 40543 | U9: =VLOOKUP(T9,L:M,2) -> 8000 | V9: =-U9 -> -8000 | W9: 40543 | X9: =VLOOKUP(W9,L:M,2) -> 8000 | Y9: =-X9 -> -8000 | Z9: 40543 | AA9: =VLOOKUP(Z9,L:M,2) -> 8000 | AB9: =-AA9 -> -8000
A10: 40662 | B10: 1.3469 | C10: 2000 | D10: 1484.8912 | E10: 12118.262 | F10: 16322.088 | G10: 16000 | H10: 16322.088 | I10: 322.0876 | J10: =VLOOKUP(A10,myPEPB!B:C,2) -> #N/A | L10: 42734 | M10: 24000 | N10: 152000 | O10: 226023.31 | P10: 74023.314 | Q10: 0.48699549 | R10: 0.1083206 | T10: 40907 | U10: =VLOOKUP(T10,L:M,2) -> 24000 | V10: =-U10 -> -24000 | W10: 40907 | X10: =VLOOKUP(W10,L:M,2) -> 24000 | Y10: =-X10 -> -24000 | Z10: 40907 | AA10: =VLOOKUP(Z10,L:M,2) -> 24000 | AB10: =-AA10 -> -24000
A11: 40694 | B11: 1.27504 | C11: 2000 | D11: 1568.5782 | E11: 13686.841 | F11: 17451.269 | G11: 18000 | H11: 17451.269 | I11: -548.73073 | J11: =VLOOKUP(A11,myPEPB!B:C,2) -> #N/A | L11: 43098 | M11: 24000 | N11: 176000 | O11: 315263.02 | P11: 139263.02 | Q11: 0.79126715 | R11: 0.13913405 | T11: 41274 | U11: =VLOOKUP(T11,L:M,2) -> 24000 | V11: =-U11 -> -24000 | W11: 41274 | X11: =VLOOKUP(W11,L:M,2) -> 24000 | Y11: =-X11 -> -24000 | Z11: 41274 | AA11: =VLOOKUP(Z11,L:M,2) -> 24000 | AB11: =-AA11 -> -24000
A12: 40724 | B12: 1.31092 | C12: 2000 | D12: 1525.6461 | E12: 15212.487 | F12: 19942.353 | G12: 20000 | H12: 19942.353 | I12: -57.646892 | J12: =VLOOKUP(A12,myPEPB!B:C,2) -> #N/A | L12: 43462 | M12: 24000 | N12: 200000 | O12: 257772.87 | P12: 57772.874 | Q12: 0.28886437 | R12: 0.053912028 | T12: 41639 | U12: =VLOOKUP(T12,L:M,2) -> 24000 | V12: =-U12 -> -24000 | W12: 41639 | X12: =VLOOKUP(W12,L:M,2) -> 24000 | Y12: =-X12 -> -24000 | Z12: 41639 | AA12: =VLOOKUP(Z12,L:M,2) -> 24000 | AB12: =-AA12 -> -24000
A13: 40753 | B13: 1.2869 | C13: 2000 | D13: 1554.1223 | E13: 16766.609 | F13: 21576.949 | G13: 22000 | H13: 21576.949 | I13: -423.05082 | J13: =VLOOKUP(A13,myPEPB!B:C,2) -> #N/A | L13: 43830 | M13: 24000 | N13: 224000 | O13: 362098.06 | P13: 138098.06 | Q13: 0.61650919 | R13: 0.091316415 | T13: 42004 | U13: =VLOOKUP(T13,L:M,2) -> 24000 | V13: =-U13 -> -24000 | W13: 42004 | X13: =VLOOKUP(W13,L:M,2) -> 24000 | Y13: =-X13 -> -24000 | Z13: 42004 | AA13: =VLOOKUP(Z13,L:M,2) -> 24000 | AB13: =-AA13 -> -24000
A14: 40786 | B14: 1.21625 | C14: 2000 | D14: 1644.3988 | E14: 18411.008 | F14: 22392.388 | G14: 24000 | H14: 22392.388 | I14: -1607.6118 | J14: =VLOOKUP(A14,myPEPB!B:C,2) -> #N/A | L14: 44196 | M14: 24000 | N14: 248000 | O14: 501442.15 | P14: 253442.15 | Q14: 1.0219442 | R14: 0.1206386 | T14: 42004 | V14: =VLOOKUP(T14,L:O,4) -> 153292.71 | W14: 42369 | X14: =VLOOKUP(W14,L:M,2) -> 24000 | Y14: =-X14 -> -24000 | Z14: 42369 | AA14: =VLOOKUP(Z14,L:M,2) -> 24000 | AB14: =-AA14 -> -24000
A15: 40816 | B15: 1.1052 | C15: 2000 | D15: 1809.6272 | E15: 20220.635 | F15: 22347.846 | G15: 26000 | H15: 22347.846 | I15: -3652.1542 | J15: =VLOOKUP(A15,myPEPB!B:C,2) -> #N/A | L15: 44561 | M15: 24000 | N15: 272000 | O15: 507834.42 | P15: 235834.42 | Q15: 0.86703831 | R15: 0.098052898 | V15: 0.14842121 | W15: 42369 | Y15: =VLOOKUP(W15,L:O,4) -> 214081.38 | Z15: 42734 | AA15: =VLOOKUP(Z15,L:M,2) -> 24000 | AB15: =-AA15 -> -24000
A16: 40847 | B16: 1.14688 | C16: 2000 | D16: 1743.8616 | E16: 21964.497 | F16: 25190.642 | G16: 28000 | H16: 25190.642 | I16: -2809.3581 | J16: =VLOOKUP(A16,myPEPB!B:C,2) -> #N/A | L16: 44925 | M16: 24000 | N16: 296000 | O16: 429691.16 | P16: 133691.16 | Q16: 0.45165931 | R16: 0.054587041 | Y16: 0.16482525 | Z16: 42734 | AB16: =VLOOKUP(Z16,L:O,4) -> 226023.31
A17: 40877 | B17: 1.07321 | C17: 2000 | D17: 1863.5682 | E17: 23828.065 | F17: 25572.517 | G17: 30000 | H17: 25572.517 | I17: -4427.4826 | J17: =VLOOKUP(A17,myPEPB!B:C,2) -> #N/A | L17: 45289 | M17: 24000 | N17: 320000 | O17: 400562.47 | P17: 80562.473 | Q17: 0.25175773 | R17: 0.030809364 | AB17: 0.1083206
A18: 40907 | B18: 0.99402 | C18: 2000 | D18: 2012.032 | E18: 25840.097 | F18: 25685.573 | G18: 32000 | H18: 25685.573 | I18: -6314.427 | J18: =VLOOKUP(A18,myPEPB!B:C,2) -> #N/A | L18: 45657 | M18: 24000 | N18: 344000 | O18: 474589.16 | P18: 130589.16 | Q18: 0.37961966 | R18: 0.040952703 | T18: 40543 | U18: =VLOOKUP(T18,L:M,2) -> 8000 | V18: =-U18 -> -8000 | W18: 40543 | X18: =VLOOKUP(W18,L:M,2) -> 8000 | Y18: =-X18 -> -8000 | Z18: 40543 | AA18: =VLOOKUP(Z18,L:M,2) -> 8000 | AB18: =-AA18 -> -8000
A19: 40939 | B19: 1.0423 | C19: 2000 | D19: 1918.8333 | E19: 27758.93 | F19: 28933.133 | G19: 34000 | H19: 28933.133 | I19: -5066.8671 | J19: =VLOOKUP(A19,myPEPB!B:C,2) -> #N/A | T19: 40907 | U19: =VLOOKUP(T19,L:M,2) -> 24000 | V19: =-U19 -> -24000 | W19: 40907 | X19: =VLOOKUP(W19,L:M,2) -> 24000 | Y19: =-X19 -> -24000 | Z19: 40907 | AA19: =VLOOKUP(Z19,L:M,2) -> 24000 | AB19: =-AA19 -> -24000
A20: 40968 | B20: 1.13051 | C20: 2000 | D20: 1769.1131 | E20: 29528.043 | F20: 33381.748 | G20: 36000 | H20: 33381.748 | I20: -2618.2519 | J20: =VLOOKUP(A20,myPEPB!B:C,2) -> #N/A | T20: 41274 | U20: =VLOOKUP(T20,L:M,2) -> 24000 | V20: =-U20 -> -24000 | W20: 41274 | X20: =VLOOKUP(W20,L:M,2) -> 24000 | Y20: =-X20 -> -24000 | Z20: 41274 | AA20: =VLOOKUP(Z20,L:M,2) -> 24000 | AB20: =-AA20 -> -24000
A21: 40998 | B21: 1.04944 | C21: 2000 | D21: 1905.7783 | E21: 31433.821 | F21: 32987.91 | G21: 38000 | H21: 32987.91 | I21: -5012.0904 | J21: =VLOOKUP(A21,myPEPB!B:C,2) -> #N/A | T21: 41639 | U21: =VLOOKUP(T21,L:M,2) -> 24000 | V21: =-U21 -> -24000 | W21: 41639 | X21: =VLOOKUP(W21,L:M,2) -> 24000 | Y21: =-X21 -> -24000 | Z21: 41639 | AA21: =VLOOKUP(Z21,L:M,2) -> 24000 | AB21: =-AA21 -> -24000
A22: 41026 | B22: 1.10586 | C22: 2000 | D22: 1808.5472 | E22: 33242.369 | F22: 36761.406 | G22: 40000 | H22: 36761.406 | I22: -3238.5942 | J22: =VLOOKUP(A22,myPEPB!B:C,2) -> #N/A | T22: 42004 | U22: =VLOOKUP(T22,L:M,2) -> 24000 | V22: =-U22 -> -24000 | W22: 42004 | X22: =VLOOKUP(W22,L:M,2) -> 24000 | Y22: =-X22 -> -24000 | Z22: 42004 | AA22: =VLOOKUP(Z22,L:M,2) -> 24000 | AB22: =-AA22 -> -24000
A23: 41060 | B23: 1.14459 | C23: 2000 | D23: 1747.3506 | E23: 34989.719 | F23: 40048.883 | G23: 42000 | H23: 40048.883 | I23: -1951.1172 | J23: =VLOOKUP(A23,myPEPB!B:C,2) -> #N/A | T23: 42369 | U23: =VLOOKUP(T23,L:M,2) -> 24000 | V23: =-U23 -> -24000 | W23: 42369 | X23: =VLOOKUP(W23,L:M,2) -> 24000 | Y23: =-X23 -> -24000 | Z23: 42369 | AA23: =VLOOKUP(Z23,L:M,2) -> 24000 | AB23: =-AA23 -> -24000
A24: 41089 | B24: 1.07804 | C24: 2000 | D24: 1855.2187 | E24: 36844.938 | F24: 39720.317 | G24: 44000 | H24: 39720.317 | I24: -4279.6831 | J24: =VLOOKUP(A24,myPEPB!B:C,2) -> #N/A | T24: 42734 | U24: =VLOOKUP(T24,L:M,2) -> 24000 | V24: =-U24 -> -24000 | W24: 42734 | X24: =VLOOKUP(W24,L:M,2) -> 24000 | Y24: =-X24 -> -24000 | Z24: 42734 | AA24: =VLOOKUP(Z24,L:M,2) -> 24000 | AB24: =-AA24 -> -24000
A25: 41121 | B25: 1.00638 | C25: 2000 | D25: 1987.3209 | E25: 38832.259 | F25: 39080.009 | G25: 46000 | H25: 39080.009 | I25: -6919.9913 | J25: =VLOOKUP(A25,myPEPB!B:C,2) -> #N/A | T25: 43098 | U25: =VLOOKUP(T25,L:M,2) -> 24000 | V25: =-U25 -> -24000 | W25: 43098 | X25: =VLOOKUP(W25,L:M,2) -> 24000 | Y25: =-X25 -> -24000 | Z25: 43098 | AA25: =VLOOKUP(Z25,L:M,2) -> 24000 | AB25: =-AA25 -> -24000
A26: 41152 | B26: 0.95392 | C26: 2000 | D26: 2096.6119 | E26: 40928.871 | F26: 39042.868 | G26: 48000 | H26: 39042.868 | I26: -8957.1316 | J26: =VLOOKUP(A26,myPEPB!B:C,2) -> #N/A | T26: 43098 | V26: =VLOOKUP(T26,L:O,4) -> 315263.02 | W26: 43462 | X26: =VLOOKUP(W26,L:M,2) -> 24000 | Y26: =-X26 -> -24000 | Z26: 43462 | AA26: =VLOOKUP(Z26,L:M,2) -> 24000 | AB26: =-AA26 -> -24000
A27: 41180 | B27: 0.97827 | C27: 2000 | D27: 2044.4254 | E27: 42973.296 | F27: 42039.486 | G27: 50000 | H27: 42039.486 | I27: -7960.5136 | J27: =VLOOKUP(A27,myPEPB!B:C,2) -> #N/A | V27: 0.13913405 | W27: 43462 | Y27: =VLOOKUP(W27,L:O,4) -> 257772.87 | Z27: 43830 | AA27: =VLOOKUP(Z27,L:M,2) -> 24000 | AB27: =-AA27 -> -24000
A28: 41213 | B28: 0.97197 | C28: 2000 | D28: 2057.6767 | E28: 45030.973 | F28: 43768.755 | G28: 52000 | H28: 43768.755 | I28: -8231.2454 | J28: =VLOOKUP(A28,myPEPB!B:C,2) -> #N/A | Y28: 0.053912028 | Z28: 43830 | AB28: =VLOOKUP(Z28,L:O,4) -> 362098.06
A29: 41243 | B29: 0.9187 | C29: 2000 | D29: 2176.9892 | E29: 47207.962 | F29: 43369.955 | G29: 54000 | H29: 43369.955 | I29: -10630.045 | J29: =VLOOKUP(A29,myPEPB!B:C,2) -> #N/A | AB29: 0.091316415
A30: 41274 | B30: 1.06653 | C30: 2000 | D30: 1875.2403 | E30: 49083.202 | F30: 52348.708 | G30: 56000 | H30: 52348.708 | I30: -3651.2923 | J30: =VLOOKUP(A30,myPEPB!B:C,2) -> #N/A | T30: 40543 | U30: =VLOOKUP(T30,L:M,2) -> 8000 | V30: =-U30 -> -8000 | W30: 40543 | X30: =VLOOKUP(W30,L:M,2) -> 8000 | Y30: =-X30 -> -8000 | Z30: 40543 | AA30: 8000 | AB30: =-AA30 -> -8000
A31: 41305 | B31: 1.12004 | C31: 2000 | D31: 1785.6505 | E31: 50868.853 | F31: 56975.15 | G31: 58000 | H31: 56975.15 | I31: -1024.8501 | J31: =VLOOKUP(A31,myPEPB!B:C,2) -> #N/A | T31: 40907 | U31: =VLOOKUP(T31,L:M,2) -> 24000 | V31: =-U31 -> -24000 | W31: 40907 | X31: =VLOOKUP(W31,L:M,2) -> 24000 | Y31: =-X31 -> -24000 | Z31: 40907 | AA31: 24000 | AB31: =-AA31 -> -24000
A32: 41333 | B32: 1.13284 | C32: 2000 | D32: 1765.4744 | E32: 52634.327 | F32: 59626.271 | G32: 60000 | H32: 59626.271 | I32: -373.7288 | J32: =VLOOKUP(A32,myPEPB!B:C,2) -> #N/A | T32: 41274 | U32: =VLOOKUP(T32,L:M,2) -> 24000 | V32: =-U32 -> -24000 | W32: 41274 | X32: =VLOOKUP(W32,L:M,2) -> 24000 | Y32: =-X32 -> -24000 | Z32: 41274 | AA32: 24000 | AB32: =-AA32 -> -24000
A33: 41362 | B33: 1.08123 | C33: 2000 | D33: 1849.7452 | E33: 54484.072 | F33: 58909.814 | G33: 62000 | H33: 58909.814 | I33: -3090.1864 | J33: =VLOOKUP(A33,myPEPB!B:C,2) -> #N/A | T33: 41639 | U33: =VLOOKUP(T33,L:M,2) -> 24000 | V33: =-U33 -> -24000 | W33: 41639 | X33: =VLOOKUP(W33,L:M,2) -> 24000 | Y33: =-X33 -> -24000 | Z33: 41639 | AA33: 24000 | AB33: =-AA33 -> -24000
A34: 41390 | B34: 1.07859 | C34: 2000 | D34: 1854.2727 | E34: 56338.345 | F34: 60765.976 | G34: 64000 | H34: 60765.976 | I34: -3234.0244 | J34: =VLOOKUP(A34,myPEPB!B:C,2) -> #N/A | T34: 42004 | U34: =VLOOKUP(T34,L:M,2) -> 24000 | V34: =-U34 -> -24000 | W34: 42004 | X34: =VLOOKUP(W34,L:M,2) -> 24000 | Y34: =-X34 -> -24000 | Z34: 42004 | AA34: 24000 | AB34: =-AA34 -> -24000
A35: 41425 | B35: 1.16704 | C35: 2000 | D35: 1713.7373 | E35: 58052.082 | F35: 67749.102 | G35: 66000 | H35: 67749.102 | I35: 1749.1022 | J35: =VLOOKUP(A35,myPEPB!B:C,2) -> #N/A | T35: 42369 | U35: =VLOOKUP(T35,L:M,2) -> 24000 | V35: =-U35 -> -24000 | W35: 42369 | X35: =VLOOKUP(W35,L:M,2) -> 24000 | Y35: =-X35 -> -24000 | Z35: 42369 | AA35: 24000 | AB35: =-AA35 -> -24000
A36: 41453 | B36: 1.0075 | C36: 2000 | D36: 1985.1117 | E36: 60037.194 | F36: 60487.473 | G36: 68000 | H36: 60487.473 | I36: -7512.527 | J36: =VLOOKUP(A36,myPEPB!B:C,2) -> #N/A | T36: 42734 | U36: =VLOOKUP(T36,L:M,2) -> 24000 | V36: =-U36 -> -24000 | W36: 42734 | X36: =VLOOKUP(W36,L:M,2) -> 24000 | Y36: =-X36 -> -24000 | Z36: 42734 | AA36: 24000 | AB36: =-AA36 -> -24000
A37: 41486 | B37: 1.03116 | C37: 2000 | D37: 1939.5632 | E37: 61976.757 | F37: 63907.953 | G37: 70000 | H37: 63907.953 | I37: -6092.047 | J37: =VLOOKUP(A37,myPEPB!B:C,2) -> #N/A | T37: 43098 | U37: =VLOOKUP(T37,L:M,2) -> 24000 | V37: =-U37 -> -24000 | W37: 43098 | X37: =VLOOKUP(W37,L:M,2) -> 24000 | Y37: =-X37 -> -24000 | Z37: 43098 | AA37: 24000 | AB37: =-AA37 -> -24000
A38: 41516 | B38: 1.1031 | C38: 2000 | D38: 1813.0723 | E38: 63789.83 | F38: 70366.561 | G38: 72000 | H38: 70366.561 | I38: -1633.439 | J38: =VLOOKUP(A38,myPEPB!B:C,2) -> #N/A | T38: 43462 | U38: =VLOOKUP(T38,L:M,2) -> 24000 | V38: =-U38 -> -24000 | W38: 43462 | X38: =VLOOKUP(W38,L:M,2) -> 24000 | Y38: =-X38 -> -24000 | Z38: 43462 | AA38: 24000 | AB38: =-AA38 -> -24000
A39: 41547 | B39: 1.16877 | C39: 2000 | D39: 1711.2007 | E39: 65501.03 | F39: 76555.639 | G39: 74000 | H39: 76555.639 | I39: 2555.6391 | J39: =VLOOKUP(A39,myPEPB!B:C,2) -> #N/A | T39: 43830 | U39: =VLOOKUP(T39,L:M,2) -> 24000 | V39: =-U39 -> -24000 | W39: 43830 | X39: =VLOOKUP(W39,L:M,2) -> 24000 | Y39: =-X39 -> -24000 | Z39: 43830 | AA39: 24000 | AB39: =-AA39 -> -24000
A40: 41578 | B40: 1.17233 | C40: 2000 | D40: 1706.0043 | E40: 67207.034 | F40: 78788.823 | G40: 76000 | H40: 78788.823 | I40: 2788.8227 | J40: =VLOOKUP(A40,myPEPB!B:C,2) -> #N/A | T40: 44196 | U40: =VLOOKUP(T40,L:M,2) -> 24000 | V40: =-U40 -> -24000 | W40: 44196 | X40: =VLOOKUP(W40,L:M,2) -> 24000 | Y40: =-X40 -> -24000 | Z40: 44196 | AA40: 24000 | AB40: =-AA40 -> -24000
...

Sheet myPEPB
B1: DATE | C1: 399378
C2: PE | D2: PE MEAN
A3: 1 | B3: 44295 | C3: 16.26 | D3: =C3 -> 16.26
A4: =A3+1 -> 2 | B4: 44298 | C4: 16.07 | D4: =SUM($C$3:C4)/A4 -> 16.165
A5: =A4+1 -> 3 | B5: 44299 | C5: 16.06 | D5: =SUM($C$3:C5)/A5 -> 16.13
A6: =A5+1 -> 4 | B6: 44300 | C6: 16.18 | D6: =SUM($C$3:C6)/A6 -> 16.1425
A7: =A6+1 -> 5 | B7: 44301 | C7: 16.07 | D7: =SUM($C$3:C7)/A7 -> 16.128
A8: =A7+1 -> 6 | B8: 44302 | C8: 16.16 | D8: =SUM($C$3:C8)/A8 -> 16.133333
A9: =A8+1 -> 7 | B9: 44305 | C9: 16.5 | D9: =SUM($C$3:C9)/A9 -> 16.185714
A10: =A9+1 -> 8 | B10: 44306 | C10: 16.49 | D10: =SUM($C$3:C10)/A10 -> 16.22375
A11: =A10+1 -> 9 | B11: 44307 | C11: 16.54 | D11: =SUM($C$3:C11)/A11 -> 16.258889
A12: =A11+1 -> 10 | B12: 44308 | C12: 16.51 | D12: =SUM($C$3:C12)/A12 -> 16.284
A13: =A12+1 -> 11 | B13: 44309 | C13: 16.66 | D13: =SUM($C$3:C13)/A13 -> 16.318182
A14: =A13+1 -> 12 | B14: 44312 | C14: 16.47 | D14: =SUM($C$3:C14)/A14 -> 16.330833
A15: =A14+1 -> 13 | B15: 44313 | C15: 16.54 | D15: =SUM($C$3:C15)/A15 -> 16.346923
... A121: =A120+1 -> 119 | B121: 44469 | C121: 12.9 | D121: =SUM($C$3:C121)/A121 -> 14.415966
A122: =A121+1 -> 120 | B122: 2021/10/8 | C122: 13.03 | D122: =SUM($C$3:C122)/A122 -> 14.404417
A123: =A122+1 -> 121 | B123: 2021/10/11 | C123: 13.04 | D123: =SUM($C$3:C123)/A123 -> 14.39314
A124: =A123+1 -> 122 | B124: 2021/10/12 | C124: 12.93 | D124: =SUM($C$3:C124)/A124 -> 14.381148
A125: =A124+1 -> 123 | B125: 2021/10/13 | C125: 13.03 | D125: =SUM($C$3:C125)/A125 -> 14.370163
A126: =A125+1 -> 124 | B126: 2021/10/14 | C126: 12.97 | D126: =SUM($C$3:C126)/A126 -> 14.358871
A127: =A126+1 -> 125 | B127: 2021/10/15 | C127: 13.01 | D127: =SUM($C$3:C127)/A127 -> 14.34808
A128: =A127+1 -> 126 | B128: 2021/10/18 | C128: 12.86 | D128: =SUM($C$3:C128)/A128 -> 14.33627
A129: =A128+1 -> 127 | B129: 2021/10/19 | C129: 12.98 | D129: =SUM($C$3:C129)/A129 -> 14.325591
A130: =A129+1 -> 128 | B130: 2021/10/20 | C130: 12.93 | D130: =SUM($C$3:C130)/A130 -> 14.314688
A131: =A130+1 -> 129 | B131: 2021/10/21 | C131: 12.99 | D131: =SUM($C$3:C131)/A131 -> 14.304419
A132: =A131+1 -> 130 | B132: 2021/10/22 | C132: 13.03 | D132: =SUM($C$3:C132)/A132 -> 14.294615
A133: =A132+1 -> 131 | B133: 2021/10/25 | C133: 13.07 | D133: =SUM($C$3:C133)/A133 -> 14.285267
... A135: =A134+1 -> 133 | B135: 2021/10/27 | C135: 12.87 | D135: =SUM($C$3:C135)/A135 -> 14.265113
A136: =A135+1 -> 134 | B136: 44497 | C136: 12.78 | D136: =SUM($C$3:C136)/A136 -> 14.25403
A137: =A136+1 -> 135 | B137: 44498 | C137: 12.84 | D137: =SUM($C$3:C137)/A137 -> 14.243556
A138: =A137+1 -> 136 | B138: 2021/11/1 | C138: 12.59 | D138: =SUM($C$3:C138)/A138 -> 14.231397
A139: =A138+1 -> 137 | B139: 2021/11/2 | C139: 12.42 | D139: =SUM($C$3:C139)/A139 -> 14.218175
A140: =A139+1 -> 138 | B140: 2021/11/3 | C140: 12.38 | D140: =SUM($C$3:C140)/A140 -> 14.204855
A141: =A140+1 -> 139 | B141: 2021/11/4 | C141: 12.5 | D141: =SUM($C$3:C141)/A141 -> 14.19259
A142: =A141+1 -> 140 | B142: 2021/11/5 | C142: 12.43 | D142: =SUM($C$3:C142)/A142 -> 14.18
A143: =A142+1 -> 141 | B143: 2021/11/8 | C143: 12.42 | D143: =SUM($C$3:C143)/A143 -> 14.167518
A144: =A143+1 -> 142 | B144: 2021/11/9 | C144: 12.39 | D144: =SUM($C$3:C144)/A144 -> 14.155
A145: =A144+1 -> 143 | B145: 2021/11/10 | C145: 12.32 | D145: =SUM($C$3:C145)/A145 -> 14.142168
A146: =A145+1 -> 144 | B146: 2021/11/11 | C146: 12.49 | D146: =SUM($C$3:C146)/A146 -> 14.130694
...
